2019-06-27 22:24:33,695 [ERROR]  Exception occurred while handling uri: unknown
NoneType: None
2019-06-27 22:24:33,798 [ERROR]  Exception occurred while handling uri: unknown
NoneType: None
2019-06-27 22:28:18,242 [ERROR]  Exception occurred while handling uri: unknown
NoneType: None
2019-06-27 22:31:03,759 [ERROR]  Exception occurred in one of response middleware handlers
Traceback (most recent call last):
  File "d:\anaconda3\envs\rasa-py3.6\lib\site-packages\sanic\app.py", line 958, in handle_request
    request, response
  File "d:\anaconda3\envs\rasa-py3.6\lib\site-packages\spf\framework.py", line 543, in _run_response_middleware
    _response = await _response
  File "d:\anaconda3\envs\rasa-py3.6\lib\site-packages\sanic_cors\extension.py", line 266, in unapplied_cors_response_middleware
    set_cors_headers(req, resp, context, res_options)
  File "d:\anaconda3\envs\rasa-py3.6\lib\site-packages\sanic_cors\core.py", line 248, in set_cors_headers
    if resp.headers is None:
AttributeError: 'list' object has no attribute 'headers'
2019-06-27 22:42:11,172 [ERROR]  Exception occurred while handling uri: 'http://localhost:5005/socket.io/?EIO=3&transport=polling&t=MkPcUQo'
Traceback (most recent call last):
  File "d:\anaconda3\envs\rasa-py3.6\lib\site-packages\sanic\app.py", line 893, in handle_request
    handler, args, kwargs, uri = self.router.get(request)
  File "d:\anaconda3\envs\rasa-py3.6\lib\site-packages\sanic\router.py", line 407, in get
    return self._get(request.path, request.method, "")
  File "d:\anaconda3\envs\rasa-py3.6\lib\site-packages\sanic\router.py", line 469, in _get
    raise NotFound("Requested URL {} not found".format(url))
sanic.exceptions.NotFound: Requested URL /socket.io/ not found
2019-06-27 22:42:43,997 [ERROR]  Exception occurred while handling uri: 'http://localhost:5005/socket.io/?EIO=3&transport=polling&t=MkPcWHq'
Traceback (most recent call last):
  File "d:\anaconda3\envs\rasa-py3.6\lib\site-packages\sanic\app.py", line 893, in handle_request
    handler, args, kwargs, uri = self.router.get(request)
  File "d:\anaconda3\envs\rasa-py3.6\lib\site-packages\sanic\router.py", line 407, in get
    return self._get(request.path, request.method, "")
  File "d:\anaconda3\envs\rasa-py3.6\lib\site-packages\sanic\router.py", line 469, in _get
    raise NotFound("Requested URL {} not found".format(url))
sanic.exceptions.NotFound: Requested URL /socket.io/ not found
2019-06-27 22:42:44,000 [ERROR]  Exception occurred while handling uri: 'http://localhost:5005/socket.io/?EIO=3&transport=polling&t=MkPccOW'
Traceback (most recent call last):
  File "d:\anaconda3\envs\rasa-py3.6\lib\site-packages\sanic\app.py", line 893, in handle_request
    handler, args, kwargs, uri = self.router.get(request)
  File "d:\anaconda3\envs\rasa-py3.6\lib\site-packages\sanic\router.py", line 407, in get
    return self._get(request.path, request.method, "")
  File "d:\anaconda3\envs\rasa-py3.6\lib\site-packages\sanic\router.py", line 469, in _get
    raise NotFound("Requested URL {} not found".format(url))
sanic.exceptions.NotFound: Requested URL /socket.io/ not found
2019-06-27 22:42:51,434 [ERROR]  Exception occurred while handling uri: 'http://localhost:5005/socket.io/?EIO=3&transport=polling&t=MkPceIj'
Traceback (most recent call last):
  File "d:\anaconda3\envs\rasa-py3.6\lib\site-packages\sanic\app.py", line 893, in handle_request
    handler, args, kwargs, uri = self.router.get(request)
  File "d:\anaconda3\envs\rasa-py3.6\lib\site-packages\sanic\router.py", line 407, in get
    return self._get(request.path, request.method, "")
  File "d:\anaconda3\envs\rasa-py3.6\lib\site-packages\sanic\router.py", line 469, in _get
    raise NotFound("Requested URL {} not found".format(url))
sanic.exceptions.NotFound: Requested URL /socket.io/ not found
2019-06-27 22:43:31,191 [ERROR]  Exception occurred while handling uri: 'http://localhost:5005/socket.io/?EIO=3&transport=polling&t=MkPcg6w'
Traceback (most recent call last):
  File "d:\anaconda3\envs\rasa-py3.6\lib\site-packages\sanic\app.py", line 893, in handle_request
    handler, args, kwargs, uri = self.router.get(request)
  File "d:\anaconda3\envs\rasa-py3.6\lib\site-packages\sanic\router.py", line 407, in get
    return self._get(request.path, request.method, "")
  File "d:\anaconda3\envs\rasa-py3.6\lib\site-packages\sanic\router.py", line 469, in _get
    raise NotFound("Requested URL {} not found".format(url))
sanic.exceptions.NotFound: Requested URL /socket.io/ not found
2019-06-27 22:43:31,192 [ERROR]  Exception occurred while handling uri: 'http://localhost:5005/socket.io/?EIO=3&transport=polling&t=MkPcmDb'
Traceback (most recent call last):
  File "d:\anaconda3\envs\rasa-py3.6\lib\site-packages\sanic\app.py", line 893, in handle_request
    handler, args, kwargs, uri = self.router.get(request)
  File "d:\anaconda3\envs\rasa-py3.6\lib\site-packages\sanic\router.py", line 407, in get
    return self._get(request.path, request.method, "")
  File "d:\anaconda3\envs\rasa-py3.6\lib\site-packages\sanic\router.py", line 469, in _get
    raise NotFound("Requested URL {} not found".format(url))
sanic.exceptions.NotFound: Requested URL /socket.io/ not found
2019-06-27 22:43:43,180 [ERROR]  Exception occurred while handling uri: 'http://localhost:5005/socket.io/?EIO=3&transport=polling&t=MkPcpq4'
Traceback (most recent call last):
  File "d:\anaconda3\envs\rasa-py3.6\lib\site-packages\sanic\app.py", line 893, in handle_request
    handler, args, kwargs, uri = self.router.get(request)
  File "d:\anaconda3\envs\rasa-py3.6\lib\site-packages\sanic\router.py", line 407, in get
    return self._get(request.path, request.method, "")
  File "d:\anaconda3\envs\rasa-py3.6\lib\site-packages\sanic\router.py", line 469, in _get
    raise NotFound("Requested URL {} not found".format(url))
sanic.exceptions.NotFound: Requested URL /socket.io/ not found
2019-06-28 08:44:22,445 [ERROR]  Exception occurred while handling uri: unknown
NoneType: None
2019-06-28 08:44:22,536 [ERROR]  Exception occurred while handling uri: unknown
NoneType: None
2019-06-28 08:45:43,462 [ERROR]  Exception occurred in one of response middleware handlers
Traceback (most recent call last):
  File "d:\anaconda3\envs\rasa-py3.6\lib\site-packages\sanic\app.py", line 958, in handle_request
    request, response
  File "d:\anaconda3\envs\rasa-py3.6\lib\site-packages\spf\framework.py", line 543, in _run_response_middleware
    _response = await _response
  File "d:\anaconda3\envs\rasa-py3.6\lib\site-packages\sanic_cors\extension.py", line 266, in unapplied_cors_response_middleware
    set_cors_headers(req, resp, context, res_options)
  File "d:\anaconda3\envs\rasa-py3.6\lib\site-packages\sanic_cors\core.py", line 248, in set_cors_headers
    if resp.headers is None:
AttributeError: 'list' object has no attribute 'headers'
2019-06-28 08:46:47,340 [ERROR]  Exception occurred while handling uri: unknown
NoneType: None
2019-06-28 08:46:47,423 [ERROR]  Exception occurred while handling uri: unknown
NoneType: None
2019-06-28 08:46:54,248 [ERROR]  Exception occurred in one of response middleware handlers
Traceback (most recent call last):
  File "d:\anaconda3\envs\rasa-py3.6\lib\site-packages\sanic\app.py", line 958, in handle_request
    request, response
  File "d:\anaconda3\envs\rasa-py3.6\lib\site-packages\spf\framework.py", line 543, in _run_response_middleware
    _response = await _response
  File "d:\anaconda3\envs\rasa-py3.6\lib\site-packages\sanic_cors\extension.py", line 266, in unapplied_cors_response_middleware
    set_cors_headers(req, resp, context, res_options)
  File "d:\anaconda3\envs\rasa-py3.6\lib\site-packages\sanic_cors\core.py", line 248, in set_cors_headers
    if resp.headers is None:
AttributeError: 'list' object has no attribute 'headers'
2019-06-28 11:02:44,574 [ERROR]  Exception occurred in one of response middleware handlers
Traceback (most recent call last):
  File "d:\anaconda3\envs\rasa-py3.6\lib\site-packages\sanic\app.py", line 958, in handle_request
    request, response
  File "d:\anaconda3\envs\rasa-py3.6\lib\site-packages\spf\framework.py", line 543, in _run_response_middleware
    _response = await _response
  File "d:\anaconda3\envs\rasa-py3.6\lib\site-packages\sanic_cors\extension.py", line 266, in unapplied_cors_response_middleware
    set_cors_headers(req, resp, context, res_options)
  File "d:\anaconda3\envs\rasa-py3.6\lib\site-packages\sanic_cors\core.py", line 248, in set_cors_headers
    if resp.headers is None:
AttributeError: 'list' object has no attribute 'headers'
2019-06-28 11:04:21,174 [ERROR]  Exception occurred while handling uri: unknown
NoneType: None
2019-06-28 11:04:21,236 [ERROR]  Exception occurred while handling uri: unknown
NoneType: None
2019-07-02 21:48:07,896 [ERROR]  Exception occurred in one of response middleware handlers
Traceback (most recent call last):
  File "d:\anaconda3\envs\rasa-py3.6\lib\site-packages\sanic\app.py", line 958, in handle_request
    request, response
  File "d:\anaconda3\envs\rasa-py3.6\lib\site-packages\spf\framework.py", line 543, in _run_response_middleware
    _response = await _response
  File "d:\anaconda3\envs\rasa-py3.6\lib\site-packages\sanic_cors\extension.py", line 266, in unapplied_cors_response_middleware
    set_cors_headers(req, resp, context, res_options)
  File "d:\anaconda3\envs\rasa-py3.6\lib\site-packages\sanic_cors\core.py", line 248, in set_cors_headers
    if resp.headers is None:
AttributeError: 'list' object has no attribute 'headers'
2019-07-02 21:49:26,831 [ERROR]  Exception occurred in one of response middleware handlers
Traceback (most recent call last):
  File "d:\anaconda3\envs\rasa-py3.6\lib\site-packages\sanic\app.py", line 958, in handle_request
    request, response
  File "d:\anaconda3\envs\rasa-py3.6\lib\site-packages\spf\framework.py", line 543, in _run_response_middleware
    _response = await _response
  File "d:\anaconda3\envs\rasa-py3.6\lib\site-packages\sanic_cors\extension.py", line 266, in unapplied_cors_response_middleware
    set_cors_headers(req, resp, context, res_options)
  File "d:\anaconda3\envs\rasa-py3.6\lib\site-packages\sanic_cors\core.py", line 248, in set_cors_headers
    if resp.headers is None:
AttributeError: 'list' object has no attribute 'headers'
2019-07-02 21:52:01,824 [ERROR]  Exception occurred while handling uri: unknown
NoneType: None
2019-07-02 21:52:01,886 [ERROR]  Exception occurred while handling uri: unknown
NoneType: None
2019-07-02 21:56:47,468 [ERROR]  Exception occurred while handling uri: unknown
NoneType: None
2019-07-02 21:56:47,544 [ERROR]  Exception occurred while handling uri: unknown
NoneType: None
2019-07-02 22:30:05,469 [ERROR]  Exception occurred while handling uri: unknown
NoneType: None
2019-07-02 22:30:05,749 [ERROR]  Exception occurred while handling uri: unknown
NoneType: None
2019-07-02 22:43:06,140 [ERROR]  Exception occurred while handling uri: unknown
NoneType: None
2019-07-02 22:43:06,207 [ERROR]  Exception occurred while handling uri: unknown
NoneType: None
2019-07-02 22:47:00,356 [ERROR]  Exception occurred while handling uri: unknown
NoneType: None
2019-07-02 22:55:17,948 [ERROR]  Exception occurred in one of response middleware handlers
Traceback (most recent call last):
  File "d:\anaconda3\envs\rasa-py3.6\lib\site-packages\sanic\app.py", line 958, in handle_request
    request, response
  File "d:\anaconda3\envs\rasa-py3.6\lib\site-packages\spf\framework.py", line 543, in _run_response_middleware
    _response = await _response
  File "d:\anaconda3\envs\rasa-py3.6\lib\site-packages\sanic_cors\extension.py", line 266, in unapplied_cors_response_middleware
    set_cors_headers(req, resp, context, res_options)
  File "d:\anaconda3\envs\rasa-py3.6\lib\site-packages\sanic_cors\core.py", line 248, in set_cors_headers
    if resp.headers is None:
AttributeError: 'list' object has no attribute 'headers'
2019-07-02 22:56:58,842 [ERROR]  Exception occurred while handling uri: unknown
NoneType: None
2019-07-02 22:56:58,917 [ERROR]  Exception occurred while handling uri: unknown
NoneType: None
2019-07-03 08:14:16,728 [ERROR]  Exception occurred while handling uri: unknown
NoneType: None
2019-07-03 08:14:16,797 [ERROR]  Exception occurred while handling uri: unknown
NoneType: None
2019-07-03 14:15:23,257 [ERROR]  Exception occurred while handling uri: 'http://localhost:5005/favicon.ico'
Traceback (most recent call last):
  File "d:\anaconda3\envs\rasa-py3.6\lib\site-packages\sanic\app.py", line 893, in handle_request
    handler, args, kwargs, uri = self.router.get(request)
  File "d:\anaconda3\envs\rasa-py3.6\lib\site-packages\sanic\router.py", line 407, in get
    return self._get(request.path, request.method, "")
  File "d:\anaconda3\envs\rasa-py3.6\lib\site-packages\sanic\router.py", line 469, in _get
    raise NotFound("Requested URL {} not found".format(url))
sanic.exceptions.NotFound: Requested URL /favicon.ico not found
2019-07-03 14:18:30,873 [ERROR]  Exception occurred in one of response middleware handlers
Traceback (most recent call last):
  File "d:\anaconda3\envs\rasa-py3.6\lib\site-packages\sanic\app.py", line 958, in handle_request
    request, response
  File "d:\anaconda3\envs\rasa-py3.6\lib\site-packages\spf\framework.py", line 543, in _run_response_middleware
    _response = await _response
  File "d:\anaconda3\envs\rasa-py3.6\lib\site-packages\sanic_cors\extension.py", line 266, in unapplied_cors_response_middleware
    set_cors_headers(req, resp, context, res_options)
  File "d:\anaconda3\envs\rasa-py3.6\lib\site-packages\sanic_cors\core.py", line 248, in set_cors_headers
    if resp.headers is None:
AttributeError: 'list' object has no attribute 'headers'
2019-07-07 23:08:25,831 [ERROR]  Exception occurred while handling uri: unknown
NoneType: None
2019-07-07 23:08:25,892 [ERROR]  Exception occurred while handling uri: unknown
NoneType: None
2019-07-07 23:22:09,765 [ERROR]  Unable to start server
Traceback (most recent call last):
  File "d:\anaconda3\envs\rasa-py3.6\lib\site-packages\sanic\server.py", line 745, in serve
    http_server = loop.run_until_complete(server_coroutine)
  File "d:\anaconda3\envs\rasa-py3.6\lib\asyncio\base_events.py", line 466, in run_until_complete
    raise RuntimeError('Event loop stopped before Future completed.')
RuntimeError: Event loop stopped before Future completed.
2019-07-08 07:59:38,659 [ERROR]  Exception occurred while handling uri: unknown
NoneType: None
2019-07-08 07:59:38,749 [ERROR]  Exception occurred while handling uri: unknown
NoneType: None
2019-07-08 08:08:29,333 [ERROR]  Exception occurred in one of response middleware handlers
Traceback (most recent call last):
  File "d:\anaconda3\envs\rasa-py3.6\lib\site-packages\sanic\app.py", line 958, in handle_request
    request, response
  File "d:\anaconda3\envs\rasa-py3.6\lib\site-packages\spf\framework.py", line 543, in _run_response_middleware
    _response = await _response
  File "d:\anaconda3\envs\rasa-py3.6\lib\site-packages\sanic_cors\extension.py", line 266, in unapplied_cors_response_middleware
    set_cors_headers(req, resp, context, res_options)
  File "d:\anaconda3\envs\rasa-py3.6\lib\site-packages\sanic_cors\core.py", line 248, in set_cors_headers
    if resp.headers is None:
AttributeError: 'list' object has no attribute 'headers'
2019-07-08 08:17:07,566 [ERROR]  Exception occurred while handling uri: unknown
NoneType: None
2019-07-08 08:17:07,655 [ERROR]  Exception occurred while handling uri: unknown
NoneType: None
2019-07-08 08:26:45,723 [ERROR]  Exception occurred in one of response middleware handlers
Traceback (most recent call last):
  File "d:\anaconda3\envs\rasa-py3.6\lib\site-packages\sanic\app.py", line 958, in handle_request
    request, response
  File "d:\anaconda3\envs\rasa-py3.6\lib\site-packages\spf\framework.py", line 543, in _run_response_middleware
    _response = await _response
  File "d:\anaconda3\envs\rasa-py3.6\lib\site-packages\sanic_cors\extension.py", line 266, in unapplied_cors_response_middleware
    set_cors_headers(req, resp, context, res_options)
  File "d:\anaconda3\envs\rasa-py3.6\lib\site-packages\sanic_cors\core.py", line 248, in set_cors_headers
    if resp.headers is None:
AttributeError: 'list' object has no attribute 'headers'
2019-07-08 08:27:39,731 [ERROR]  Exception occurred in one of response middleware handlers
Traceback (most recent call last):
  File "d:\anaconda3\envs\rasa-py3.6\lib\site-packages\sanic\app.py", line 958, in handle_request
    request, response
  File "d:\anaconda3\envs\rasa-py3.6\lib\site-packages\spf\framework.py", line 543, in _run_response_middleware
    _response = await _response
  File "d:\anaconda3\envs\rasa-py3.6\lib\site-packages\sanic_cors\extension.py", line 266, in unapplied_cors_response_middleware
    set_cors_headers(req, resp, context, res_options)
  File "d:\anaconda3\envs\rasa-py3.6\lib\site-packages\sanic_cors\core.py", line 248, in set_cors_headers
    if resp.headers is None:
AttributeError: 'list' object has no attribute 'headers'
2019-07-08 08:27:57,044 [ERROR]  Exception occurred in one of response middleware handlers
Traceback (most recent call last):
  File "d:\anaconda3\envs\rasa-py3.6\lib\site-packages\sanic\app.py", line 958, in handle_request
    request, response
  File "d:\anaconda3\envs\rasa-py3.6\lib\site-packages\spf\framework.py", line 543, in _run_response_middleware
    _response = await _response
  File "d:\anaconda3\envs\rasa-py3.6\lib\site-packages\sanic_cors\extension.py", line 266, in unapplied_cors_response_middleware
    set_cors_headers(req, resp, context, res_options)
  File "d:\anaconda3\envs\rasa-py3.6\lib\site-packages\sanic_cors\core.py", line 248, in set_cors_headers
    if resp.headers is None:
AttributeError: 'list' object has no attribute 'headers'
2019-07-08 08:36:52,138 [ERROR]  Exception occurred while handling uri: unknown
NoneType: None
2019-07-08 08:36:52,227 [ERROR]  Exception occurred while handling uri: unknown
NoneType: None
2019-07-08 10:51:51,050 [ERROR]  Exception occurred while handling uri: unknown
NoneType: None
2019-07-08 10:51:51,152 [ERROR]  Exception occurred while handling uri: unknown
NoneType: None
2019-07-08 11:01:44,612 [ERROR]  Exception occurred in one of response middleware handlers
Traceback (most recent call last):
  File "d:\anaconda3\envs\rasa-py3.6\lib\site-packages\sanic\app.py", line 958, in handle_request
    request, response
  File "d:\anaconda3\envs\rasa-py3.6\lib\site-packages\spf\framework.py", line 543, in _run_response_middleware
    _response = await _response
  File "d:\anaconda3\envs\rasa-py3.6\lib\site-packages\sanic_cors\extension.py", line 266, in unapplied_cors_response_middleware
    set_cors_headers(req, resp, context, res_options)
  File "d:\anaconda3\envs\rasa-py3.6\lib\site-packages\sanic_cors\core.py", line 248, in set_cors_headers
    if resp.headers is None:
AttributeError: 'list' object has no attribute 'headers'
2019-07-08 11:02:38,661 [ERROR]  Exception occurred in one of response middleware handlers
Traceback (most recent call last):
  File "d:\anaconda3\envs\rasa-py3.6\lib\site-packages\sanic\app.py", line 958, in handle_request
    request, response
  File "d:\anaconda3\envs\rasa-py3.6\lib\site-packages\spf\framework.py", line 543, in _run_response_middleware
    _response = await _response
  File "d:\anaconda3\envs\rasa-py3.6\lib\site-packages\sanic_cors\extension.py", line 266, in unapplied_cors_response_middleware
    set_cors_headers(req, resp, context, res_options)
  File "d:\anaconda3\envs\rasa-py3.6\lib\site-packages\sanic_cors\core.py", line 248, in set_cors_headers
    if resp.headers is None:
AttributeError: 'list' object has no attribute 'headers'
2019-07-08 11:03:40,508 [ERROR]  Exception occurred while handling uri: unknown
NoneType: None
2019-07-08 11:03:40,596 [ERROR]  Exception occurred while handling uri: unknown
NoneType: None
2019-07-08 11:05:31,353 [ERROR]  Exception occurred while handling uri: unknown
NoneType: None
2019-07-08 11:05:31,396 [ERROR]  Exception occurred while handling uri: unknown
NoneType: None
2019-07-08 11:05:31,406 [ERROR]  Exception occurred while handling uri: unknown
NoneType: None
2019-07-08 11:05:31,412 [ERROR]  Exception occurred while handling uri: unknown
NoneType: None
2019-07-08 11:08:27,967 [ERROR]  Exception occurred in one of response middleware handlers
Traceback (most recent call last):
  File "d:\anaconda3\envs\rasa-py3.6\lib\site-packages\sanic\app.py", line 958, in handle_request
    request, response
  File "d:\anaconda3\envs\rasa-py3.6\lib\site-packages\spf\framework.py", line 543, in _run_response_middleware
    _response = await _response
  File "d:\anaconda3\envs\rasa-py3.6\lib\site-packages\sanic_cors\extension.py", line 266, in unapplied_cors_response_middleware
    set_cors_headers(req, resp, context, res_options)
  File "d:\anaconda3\envs\rasa-py3.6\lib\site-packages\sanic_cors\core.py", line 248, in set_cors_headers
    if resp.headers is None:
AttributeError: 'list' object has no attribute 'headers'
2019-07-08 11:08:29,612 [ERROR]  Exception occurred in one of response middleware handlers
Traceback (most recent call last):
  File "d:\anaconda3\envs\rasa-py3.6\lib\site-packages\sanic\app.py", line 958, in handle_request
    request, response
  File "d:\anaconda3\envs\rasa-py3.6\lib\site-packages\spf\framework.py", line 543, in _run_response_middleware
    _response = await _response
  File "d:\anaconda3\envs\rasa-py3.6\lib\site-packages\sanic_cors\extension.py", line 266, in unapplied_cors_response_middleware
    set_cors_headers(req, resp, context, res_options)
  File "d:\anaconda3\envs\rasa-py3.6\lib\site-packages\sanic_cors\core.py", line 248, in set_cors_headers
    if resp.headers is None:
AttributeError: 'list' object has no attribute 'headers'
2019-07-08 11:10:46,167 [ERROR]  Exception occurred while handling uri: unknown
NoneType: None
2019-07-08 11:10:46,226 [ERROR]  Exception occurred while handling uri: unknown
NoneType: None
2019-07-08 11:18:08,128 [ERROR]  Exception occurred in one of response middleware handlers
Traceback (most recent call last):
  File "d:\anaconda3\envs\rasa-py3.6\lib\site-packages\sanic\app.py", line 958, in handle_request
    request, response
  File "d:\anaconda3\envs\rasa-py3.6\lib\site-packages\spf\framework.py", line 543, in _run_response_middleware
    _response = await _response
  File "d:\anaconda3\envs\rasa-py3.6\lib\site-packages\sanic_cors\extension.py", line 266, in unapplied_cors_response_middleware
    set_cors_headers(req, resp, context, res_options)
  File "d:\anaconda3\envs\rasa-py3.6\lib\site-packages\sanic_cors\core.py", line 248, in set_cors_headers
    if resp.headers is None:
AttributeError: 'list' object has no attribute 'headers'
2019-07-08 11:19:11,715 [ERROR]  Exception occurred while handling uri: unknown
NoneType: None
2019-07-08 11:19:11,793 [ERROR]  Exception occurred while handling uri: unknown
NoneType: None
2019-07-08 11:24:45,076 [ERROR]  Exception occurred in one of response middleware handlers
Traceback (most recent call last):
  File "d:\anaconda3\envs\rasa-py3.6\lib\site-packages\sanic\app.py", line 958, in handle_request
    request, response
  File "d:\anaconda3\envs\rasa-py3.6\lib\site-packages\spf\framework.py", line 543, in _run_response_middleware
    _response = await _response
  File "d:\anaconda3\envs\rasa-py3.6\lib\site-packages\sanic_cors\extension.py", line 266, in unapplied_cors_response_middleware
    set_cors_headers(req, resp, context, res_options)
  File "d:\anaconda3\envs\rasa-py3.6\lib\site-packages\sanic_cors\core.py", line 248, in set_cors_headers
    if resp.headers is None:
AttributeError: 'list' object has no attribute 'headers'
2019-07-08 11:25:47,826 [ERROR]  Exception occurred while handling uri: unknown
NoneType: None
2019-07-08 11:25:47,917 [ERROR]  Exception occurred while handling uri: unknown
NoneType: None
2019-07-08 11:26:20,882 [ERROR]  Exception occurred in one of response middleware handlers
Traceback (most recent call last):
  File "d:\anaconda3\envs\rasa-py3.6\lib\site-packages\sanic\app.py", line 958, in handle_request
    request, response
  File "d:\anaconda3\envs\rasa-py3.6\lib\site-packages\spf\framework.py", line 543, in _run_response_middleware
    _response = await _response
  File "d:\anaconda3\envs\rasa-py3.6\lib\site-packages\sanic_cors\extension.py", line 266, in unapplied_cors_response_middleware
    set_cors_headers(req, resp, context, res_options)
  File "d:\anaconda3\envs\rasa-py3.6\lib\site-packages\sanic_cors\core.py", line 248, in set_cors_headers
    if resp.headers is None:
AttributeError: 'list' object has no attribute 'headers'
2019-07-08 11:34:28,213 [ERROR]  Exception occurred while handling uri: unknown
NoneType: None
2019-07-08 11:34:28,292 [ERROR]  Exception occurred while handling uri: unknown
NoneType: None
2019-07-08 11:38:13,442 [ERROR]  Exception occurred in one of response middleware handlers
Traceback (most recent call last):
  File "d:\anaconda3\envs\rasa-py3.6\lib\site-packages\sanic\app.py", line 958, in handle_request
    request, response
  File "d:\anaconda3\envs\rasa-py3.6\lib\site-packages\spf\framework.py", line 543, in _run_response_middleware
    _response = await _response
  File "d:\anaconda3\envs\rasa-py3.6\lib\site-packages\sanic_cors\extension.py", line 266, in unapplied_cors_response_middleware
    set_cors_headers(req, resp, context, res_options)
  File "d:\anaconda3\envs\rasa-py3.6\lib\site-packages\sanic_cors\core.py", line 248, in set_cors_headers
    if resp.headers is None:
AttributeError: 'list' object has no attribute 'headers'
2019-07-09 09:43:42,307 [ERROR]  Exception occurred in one of response middleware handlers
Traceback (most recent call last):
  File "d:\anaconda3\envs\rasa-py3.6\lib\site-packages\sanic\app.py", line 958, in handle_request
    request, response
  File "d:\anaconda3\envs\rasa-py3.6\lib\site-packages\spf\framework.py", line 543, in _run_response_middleware
    _response = await _response
  File "d:\anaconda3\envs\rasa-py3.6\lib\site-packages\sanic_cors\extension.py", line 266, in unapplied_cors_response_middleware
    set_cors_headers(req, resp, context, res_options)
  File "d:\anaconda3\envs\rasa-py3.6\lib\site-packages\sanic_cors\core.py", line 248, in set_cors_headers
    if resp.headers is None:
AttributeError: 'list' object has no attribute 'headers'
2019-07-09 14:39:11,743 [ERROR]  Exception occurred while handling uri: unknown
NoneType: None
2019-07-09 14:39:11,832 [ERROR]  Exception occurred while handling uri: unknown
NoneType: None
2019-07-09 14:41:15,107 [ERROR]  Exception occurred in one of response middleware handlers
Traceback (most recent call last):
  File "d:\anaconda3\envs\rasa-py3.6\lib\site-packages\sanic\app.py", line 958, in handle_request
    request, response
  File "d:\anaconda3\envs\rasa-py3.6\lib\site-packages\spf\framework.py", line 543, in _run_response_middleware
    _response = await _response
  File "d:\anaconda3\envs\rasa-py3.6\lib\site-packages\sanic_cors\extension.py", line 266, in unapplied_cors_response_middleware
    set_cors_headers(req, resp, context, res_options)
  File "d:\anaconda3\envs\rasa-py3.6\lib\site-packages\sanic_cors\core.py", line 248, in set_cors_headers
    if resp.headers is None:
AttributeError: 'list' object has no attribute 'headers'
2019-07-11 09:50:55,847 [ERROR]  Experienced exception while trying to serve
Traceback (most recent call last):
  File "/home/baongocst/anaconda3/envs/python36/lib/python3.6/site-packages/sanic/app.py", line 1096, in run
    serve(**server_settings)
  File "/home/baongocst/anaconda3/envs/python36/lib/python3.6/site-packages/sanic/server.py", line 742, in serve
    trigger_events(before_start, loop)
  File "/home/baongocst/anaconda3/envs/python36/lib/python3.6/site-packages/sanic/server.py", line 604, in trigger_events
    loop.run_until_complete(result)
  File "uvloop/loop.pyx", line 1451, in uvloop.loop.Loop.run_until_complete
  File "/home/baongocst/anaconda3/envs/python36/lib/python3.6/site-packages/rasa/core/run.py", line 211, in load_agent_on_start
    action_endpoint=endpoints.action,
  File "/home/baongocst/anaconda3/envs/python36/lib/python3.6/site-packages/rasa/core/agent.py", line 262, in load_agent
    remote_storage=remote_storage,
  File "/home/baongocst/anaconda3/envs/python36/lib/python3.6/site-packages/rasa/core/agent.py", line 892, in load_local_model
    remote_storage=remote_storage,
  File "/home/baongocst/anaconda3/envs/python36/lib/python3.6/site-packages/rasa/core/agent.py", line 371, in load
    interpreter = NaturalLanguageInterpreter.create(nlu_model)
  File "/home/baongocst/anaconda3/envs/python36/lib/python3.6/site-packages/rasa/core/interpreter.py", line 53, in create
    return RasaNLUInterpreter(model_directory=obj)
  File "/home/baongocst/anaconda3/envs/python36/lib/python3.6/site-packages/rasa/core/interpreter.py", line 247, in __init__
    self._load_interpreter()
  File "/home/baongocst/anaconda3/envs/python36/lib/python3.6/site-packages/rasa/core/interpreter.py", line 267, in _load_interpreter
    self.interpreter = Interpreter.load(self.model_directory)
  File "/home/baongocst/anaconda3/envs/python36/lib/python3.6/site-packages/rasa/nlu/model.py", line 301, in load
    return Interpreter.create(model_metadata, component_builder, skip_validation)
  File "/home/baongocst/anaconda3/envs/python36/lib/python3.6/site-packages/rasa/nlu/model.py", line 323, in create
    components.validate_requirements(model_metadata.component_classes)
  File "/home/baongocst/anaconda3/envs/python36/lib/python3.6/site-packages/rasa/nlu/components.py", line 47, in validate_requirements
    + "Please install {}".format(", ".join(failed_imports))
Exception: Not all required packages are installed. To use this pipeline, you need to install the missing dependencies. Please install spacy
2019-07-11 14:42:02,679 [ERROR]  Exception occurred while handling uri: 'ws://localhost:5005/socket.io/?EIO=3&transport=websocket&sid=93fa29fb5f3343319b18ad5aaf043f17'
Traceback (most recent call last):
  File "/home/baongocst/anaconda3/envs/python36/lib/python3.6/site-packages/sanic/app.py", line 917, in handle_request
    response = await response
  File "/home/baongocst/anaconda3/envs/python36/lib/python3.6/site-packages/engineio/asyncio_server.py", line 222, in handle_request
    packets = await socket.handle_get_request(environ)
  File "/home/baongocst/anaconda3/envs/python36/lib/python3.6/site-packages/engineio/asyncio_socket.py", line 89, in handle_get_request
    return await getattr(self, '_upgrade_' + transport)(environ)
  File "/home/baongocst/anaconda3/envs/python36/lib/python3.6/site-packages/engineio/asyncio_socket.py", line 128, in _upgrade_websocket
    return await ws(environ)
  File "/home/baongocst/anaconda3/envs/python36/lib/python3.6/site-packages/engineio/async_drivers/sanic.py", line 122, in __call__
    await self.handler(self)
  File "/home/baongocst/anaconda3/envs/python36/lib/python3.6/site-packages/engineio/asyncio_socket.py", line 152, in _websocket_handler
    pkt = await ws.wait()
  File "/home/baongocst/anaconda3/envs/python36/lib/python3.6/site-packages/engineio/async_drivers/sanic.py", line 131, in wait
    data = await self._sock.recv()
  File "/home/baongocst/anaconda3/envs/python36/lib/python3.6/site-packages/websockets/protocol.py", line 350, in recv
    yield from self.ensure_open()
  File "/home/baongocst/anaconda3/envs/python36/lib/python3.6/site-packages/websockets/protocol.py", line 512, in ensure_open
    self.close_code, self.close_reason) from self.transfer_data_exc
websockets.exceptions.ConnectionClosed: WebSocket connection is closed: code = 1001 (going away), no reason
2019-07-11 14:42:58,738 [ERROR]  Exception occurred while handling uri: 'ws://localhost:5005/socket.io/?EIO=3&transport=websocket&sid=76da9e8df8d24de981eea731a0118ee5'
Traceback (most recent call last):
  File "/home/baongocst/anaconda3/envs/python36/lib/python3.6/site-packages/sanic/app.py", line 917, in handle_request
    response = await response
  File "/home/baongocst/anaconda3/envs/python36/lib/python3.6/site-packages/engineio/asyncio_server.py", line 222, in handle_request
    packets = await socket.handle_get_request(environ)
  File "/home/baongocst/anaconda3/envs/python36/lib/python3.6/site-packages/engineio/asyncio_socket.py", line 89, in handle_get_request
    return await getattr(self, '_upgrade_' + transport)(environ)
  File "/home/baongocst/anaconda3/envs/python36/lib/python3.6/site-packages/engineio/asyncio_socket.py", line 128, in _upgrade_websocket
    return await ws(environ)
  File "/home/baongocst/anaconda3/envs/python36/lib/python3.6/site-packages/engineio/async_drivers/sanic.py", line 122, in __call__
    await self.handler(self)
  File "/home/baongocst/anaconda3/envs/python36/lib/python3.6/site-packages/engineio/asyncio_socket.py", line 152, in _websocket_handler
    pkt = await ws.wait()
  File "/home/baongocst/anaconda3/envs/python36/lib/python3.6/site-packages/engineio/async_drivers/sanic.py", line 131, in wait
    data = await self._sock.recv()
  File "/home/baongocst/anaconda3/envs/python36/lib/python3.6/site-packages/websockets/protocol.py", line 350, in recv
    yield from self.ensure_open()
  File "/home/baongocst/anaconda3/envs/python36/lib/python3.6/site-packages/websockets/protocol.py", line 512, in ensure_open
    self.close_code, self.close_reason) from self.transfer_data_exc
websockets.exceptions.ConnectionClosed: WebSocket connection is closed: code = 1001 (going away), no reason
2019-07-11 14:59:46,225 [ERROR]  Exception occurred while handling uri: 'http://localhost:5005/socket.io/?EIO=3&transport=polling&t=MlW2hF9&sid=6cc7ae8d98d14c70b81a8e6e5707d54b'
NoneType: None
2019-07-11 14:59:47,244 [ERROR]  Exception occurred while handling uri: 'ws://localhost:5005/socket.io/?EIO=3&transport=websocket&sid=6cc7ae8d98d14c70b81a8e6e5707d54b'
Traceback (most recent call last):
  File "/home/baongocst/anaconda3/envs/python36/lib/python3.6/site-packages/sanic/app.py", line 917, in handle_request
    response = await response
  File "/home/baongocst/anaconda3/envs/python36/lib/python3.6/site-packages/engineio/asyncio_server.py", line 222, in handle_request
    packets = await socket.handle_get_request(environ)
  File "/home/baongocst/anaconda3/envs/python36/lib/python3.6/site-packages/engineio/asyncio_socket.py", line 89, in handle_get_request
    return await getattr(self, '_upgrade_' + transport)(environ)
  File "/home/baongocst/anaconda3/envs/python36/lib/python3.6/site-packages/engineio/asyncio_socket.py", line 128, in _upgrade_websocket
    return await ws(environ)
  File "/home/baongocst/anaconda3/envs/python36/lib/python3.6/site-packages/engineio/async_drivers/sanic.py", line 122, in __call__
    await self.handler(self)
  File "/home/baongocst/anaconda3/envs/python36/lib/python3.6/site-packages/engineio/asyncio_socket.py", line 152, in _websocket_handler
    pkt = await ws.wait()
  File "/home/baongocst/anaconda3/envs/python36/lib/python3.6/site-packages/engineio/async_drivers/sanic.py", line 131, in wait
    data = await self._sock.recv()
  File "/home/baongocst/anaconda3/envs/python36/lib/python3.6/site-packages/websockets/protocol.py", line 350, in recv
    yield from self.ensure_open()
  File "/home/baongocst/anaconda3/envs/python36/lib/python3.6/site-packages/websockets/protocol.py", line 512, in ensure_open
    self.close_code, self.close_reason) from self.transfer_data_exc
websockets.exceptions.ConnectionClosed: WebSocket connection is closed: code = 1005 (no status code [internal]), no reason
2019-07-17 11:09:06,069 [DEBUG]  Available web server routes: 
/webhooks/rest                                     GET                            custom_webhook_CmdlineInput.health
/webhooks/rest/webhook                             POST                           custom_webhook_CmdlineInput.receive
2019-07-17 15:01:21,685 [DEBUG]  Available web server routes: 
/webhooks/rest                                     GET                            custom_webhook_CmdlineInput.health
/webhooks/rest/webhook                             POST                           custom_webhook_CmdlineInput.receive
2019-07-17 15:09:37,592 [ERROR]  Exception occurred while handling uri: 'http://localhost:5005/socket.io/?EIO=3&transport=polling&t=Ml-yyaC'
Traceback (most recent call last):
  File "/home/baongocst/anaconda3/envs/python36/lib/python3.6/site-packages/sanic/app.py", line 893, in handle_request
    handler, args, kwargs, uri = self.router.get(request)
  File "/home/baongocst/anaconda3/envs/python36/lib/python3.6/site-packages/sanic/router.py", line 407, in get
    return self._get(request.path, request.method, "")
  File "/home/baongocst/anaconda3/envs/python36/lib/python3.6/site-packages/sanic/router.py", line 469, in _get
    raise NotFound("Requested URL {} not found".format(url))
sanic.exceptions.NotFound: Requested URL /socket.io/ not found
2019-07-17 15:09:37,607 [ERROR]  Exception occurred while handling uri: 'http://localhost:5005/socket.io/?EIO=3&transport=polling&t=Ml-z2wR'
Traceback (most recent call last):
  File "/home/baongocst/anaconda3/envs/python36/lib/python3.6/site-packages/sanic/app.py", line 893, in handle_request
    handler, args, kwargs, uri = self.router.get(request)
  File "/home/baongocst/anaconda3/envs/python36/lib/python3.6/site-packages/sanic/router.py", line 407, in get
    return self._get(request.path, request.method, "")
  File "/home/baongocst/anaconda3/envs/python36/lib/python3.6/site-packages/sanic/router.py", line 469, in _get
    raise NotFound("Requested URL {} not found".format(url))
sanic.exceptions.NotFound: Requested URL /socket.io/ not found
2019-07-17 15:09:37,615 [ERROR]  Exception occurred while handling uri: 'http://localhost:5005/socket.io/?EIO=3&transport=polling&t=Ml-z9Gh'
Traceback (most recent call last):
  File "/home/baongocst/anaconda3/envs/python36/lib/python3.6/site-packages/sanic/app.py", line 893, in handle_request
    handler, args, kwargs, uri = self.router.get(request)
  File "/home/baongocst/anaconda3/envs/python36/lib/python3.6/site-packages/sanic/router.py", line 407, in get
    return self._get(request.path, request.method, "")
  File "/home/baongocst/anaconda3/envs/python36/lib/python3.6/site-packages/sanic/router.py", line 469, in _get
    raise NotFound("Requested URL {} not found".format(url))
sanic.exceptions.NotFound: Requested URL /socket.io/ not found
2019-07-17 15:09:37,621 [ERROR]  Exception occurred while handling uri: 'http://localhost:5005/socket.io/?EIO=3&transport=polling&t=Ml-zFcx'
Traceback (most recent call last):
  File "/home/baongocst/anaconda3/envs/python36/lib/python3.6/site-packages/sanic/app.py", line 893, in handle_request
    handler, args, kwargs, uri = self.router.get(request)
  File "/home/baongocst/anaconda3/envs/python36/lib/python3.6/site-packages/sanic/router.py", line 407, in get
    return self._get(request.path, request.method, "")
  File "/home/baongocst/anaconda3/envs/python36/lib/python3.6/site-packages/sanic/router.py", line 469, in _get
    raise NotFound("Requested URL {} not found".format(url))
sanic.exceptions.NotFound: Requested URL /socket.io/ not found
2019-07-17 15:09:37,638 [ERROR]  Exception occurred while handling uri: 'http://localhost:5005/socket.io/?EIO=3&transport=polling&t=Ml-zLzD'
Traceback (most recent call last):
  File "/home/baongocst/anaconda3/envs/python36/lib/python3.6/site-packages/sanic/app.py", line 893, in handle_request
    handler, args, kwargs, uri = self.router.get(request)
  File "/home/baongocst/anaconda3/envs/python36/lib/python3.6/site-packages/sanic/router.py", line 407, in get
    return self._get(request.path, request.method, "")
  File "/home/baongocst/anaconda3/envs/python36/lib/python3.6/site-packages/sanic/router.py", line 469, in _get
    raise NotFound("Requested URL {} not found".format(url))
sanic.exceptions.NotFound: Requested URL /socket.io/ not found
2019-07-17 15:09:37,648 [ERROR]  Exception occurred while handling uri: 'http://localhost:5005/socket.io/?EIO=3&transport=polling&t=Ml-zSJS'
Traceback (most recent call last):
  File "/home/baongocst/anaconda3/envs/python36/lib/python3.6/site-packages/sanic/app.py", line 893, in handle_request
    handler, args, kwargs, uri = self.router.get(request)
  File "/home/baongocst/anaconda3/envs/python36/lib/python3.6/site-packages/sanic/router.py", line 407, in get
    return self._get(request.path, request.method, "")
  File "/home/baongocst/anaconda3/envs/python36/lib/python3.6/site-packages/sanic/router.py", line 469, in _get
    raise NotFound("Requested URL {} not found".format(url))
sanic.exceptions.NotFound: Requested URL /socket.io/ not found
2019-07-17 15:09:37,709 [ERROR]  Exception occurred while handling uri: 'http://localhost:5005/socket.io/?EIO=3&transport=polling&t=Ml-zYfi'
Traceback (most recent call last):
  File "/home/baongocst/anaconda3/envs/python36/lib/python3.6/site-packages/sanic/app.py", line 893, in handle_request
    handler, args, kwargs, uri = self.router.get(request)
  File "/home/baongocst/anaconda3/envs/python36/lib/python3.6/site-packages/sanic/router.py", line 407, in get
    return self._get(request.path, request.method, "")
  File "/home/baongocst/anaconda3/envs/python36/lib/python3.6/site-packages/sanic/router.py", line 469, in _get
    raise NotFound("Requested URL {} not found".format(url))
sanic.exceptions.NotFound: Requested URL /socket.io/ not found
2019-07-17 15:09:37,732 [ERROR]  Exception occurred while handling uri: 'http://localhost:5005/socket.io/?EIO=3&transport=polling&t=Ml-ze_x'
Traceback (most recent call last):
  File "/home/baongocst/anaconda3/envs/python36/lib/python3.6/site-packages/sanic/app.py", line 893, in handle_request
    handler, args, kwargs, uri = self.router.get(request)
  File "/home/baongocst/anaconda3/envs/python36/lib/python3.6/site-packages/sanic/router.py", line 407, in get
    return self._get(request.path, request.method, "")
  File "/home/baongocst/anaconda3/envs/python36/lib/python3.6/site-packages/sanic/router.py", line 469, in _get
    raise NotFound("Requested URL {} not found".format(url))
sanic.exceptions.NotFound: Requested URL /socket.io/ not found
2019-07-17 15:09:37,739 [ERROR]  Exception occurred while handling uri: 'http://localhost:5005/socket.io/?EIO=3&transport=polling&t=Ml-zlMB'
Traceback (most recent call last):
  File "/home/baongocst/anaconda3/envs/python36/lib/python3.6/site-packages/sanic/app.py", line 893, in handle_request
    handler, args, kwargs, uri = self.router.get(request)
  File "/home/baongocst/anaconda3/envs/python36/lib/python3.6/site-packages/sanic/router.py", line 407, in get
    return self._get(request.path, request.method, "")
  File "/home/baongocst/anaconda3/envs/python36/lib/python3.6/site-packages/sanic/router.py", line 469, in _get
    raise NotFound("Requested URL {} not found".format(url))
sanic.exceptions.NotFound: Requested URL /socket.io/ not found
2019-07-17 15:09:37,744 [ERROR]  Exception occurred while handling uri: 'http://localhost:5005/socket.io/?EIO=3&transport=polling&t=Ml-zriR'
Traceback (most recent call last):
  File "/home/baongocst/anaconda3/envs/python36/lib/python3.6/site-packages/sanic/app.py", line 893, in handle_request
    handler, args, kwargs, uri = self.router.get(request)
  File "/home/baongocst/anaconda3/envs/python36/lib/python3.6/site-packages/sanic/router.py", line 407, in get
    return self._get(request.path, request.method, "")
  File "/home/baongocst/anaconda3/envs/python36/lib/python3.6/site-packages/sanic/router.py", line 469, in _get
    raise NotFound("Requested URL {} not found".format(url))
sanic.exceptions.NotFound: Requested URL /socket.io/ not found
2019-07-17 15:09:37,751 [ERROR]  Exception occurred while handling uri: 'http://localhost:5005/socket.io/?EIO=3&transport=polling&t=Ml-zy2h'
Traceback (most recent call last):
  File "/home/baongocst/anaconda3/envs/python36/lib/python3.6/site-packages/sanic/app.py", line 893, in handle_request
    handler, args, kwargs, uri = self.router.get(request)
  File "/home/baongocst/anaconda3/envs/python36/lib/python3.6/site-packages/sanic/router.py", line 407, in get
    return self._get(request.path, request.method, "")
  File "/home/baongocst/anaconda3/envs/python36/lib/python3.6/site-packages/sanic/router.py", line 469, in _get
    raise NotFound("Requested URL {} not found".format(url))
sanic.exceptions.NotFound: Requested URL /socket.io/ not found
2019-07-17 15:09:37,757 [ERROR]  Exception occurred while handling uri: 'http://localhost:5005/socket.io/?EIO=3&transport=polling&t=Ml--2Ox'
Traceback (most recent call last):
  File "/home/baongocst/anaconda3/envs/python36/lib/python3.6/site-packages/sanic/app.py", line 893, in handle_request
    handler, args, kwargs, uri = self.router.get(request)
  File "/home/baongocst/anaconda3/envs/python36/lib/python3.6/site-packages/sanic/router.py", line 407, in get
    return self._get(request.path, request.method, "")
  File "/home/baongocst/anaconda3/envs/python36/lib/python3.6/site-packages/sanic/router.py", line 469, in _get
    raise NotFound("Requested URL {} not found".format(url))
sanic.exceptions.NotFound: Requested URL /socket.io/ not found
2019-07-17 15:09:37,772 [ERROR]  Exception occurred while handling uri: 'http://localhost:5005/socket.io/?EIO=3&transport=polling&t=Ml--F5R'
Traceback (most recent call last):
  File "/home/baongocst/anaconda3/envs/python36/lib/python3.6/site-packages/sanic/app.py", line 893, in handle_request
    handler, args, kwargs, uri = self.router.get(request)
  File "/home/baongocst/anaconda3/envs/python36/lib/python3.6/site-packages/sanic/router.py", line 407, in get
    return self._get(request.path, request.method, "")
  File "/home/baongocst/anaconda3/envs/python36/lib/python3.6/site-packages/sanic/router.py", line 469, in _get
    raise NotFound("Requested URL {} not found".format(url))
sanic.exceptions.NotFound: Requested URL /socket.io/ not found
2019-07-17 15:09:37,784 [ERROR]  Exception occurred while handling uri: 'http://localhost:5005/socket.io/?EIO=3&transport=polling&t=Ml--8lB'
Traceback (most recent call last):
  File "/home/baongocst/anaconda3/envs/python36/lib/python3.6/site-packages/sanic/app.py", line 893, in handle_request
    handler, args, kwargs, uri = self.router.get(request)
  File "/home/baongocst/anaconda3/envs/python36/lib/python3.6/site-packages/sanic/router.py", line 407, in get
    return self._get(request.path, request.method, "")
  File "/home/baongocst/anaconda3/envs/python36/lib/python3.6/site-packages/sanic/router.py", line 469, in _get
    raise NotFound("Requested URL {} not found".format(url))
sanic.exceptions.NotFound: Requested URL /socket.io/ not found
2019-07-17 15:09:37,803 [ERROR]  Exception occurred while handling uri: 'http://localhost:5005/socket.io/?EIO=3&transport=polling&t=Ml--LRh'
Traceback (most recent call last):
  File "/home/baongocst/anaconda3/envs/python36/lib/python3.6/site-packages/sanic/app.py", line 893, in handle_request
    handler, args, kwargs, uri = self.router.get(request)
  File "/home/baongocst/anaconda3/envs/python36/lib/python3.6/site-packages/sanic/router.py", line 407, in get
    return self._get(request.path, request.method, "")
  File "/home/baongocst/anaconda3/envs/python36/lib/python3.6/site-packages/sanic/router.py", line 469, in _get
    raise NotFound("Requested URL {} not found".format(url))
sanic.exceptions.NotFound: Requested URL /socket.io/ not found
2019-07-17 15:09:37,809 [ERROR]  Exception occurred while handling uri: 'http://localhost:5005/socket.io/?EIO=3&transport=polling&t=Ml--Rnx'
Traceback (most recent call last):
  File "/home/baongocst/anaconda3/envs/python36/lib/python3.6/site-packages/sanic/app.py", line 893, in handle_request
    handler, args, kwargs, uri = self.router.get(request)
  File "/home/baongocst/anaconda3/envs/python36/lib/python3.6/site-packages/sanic/router.py", line 407, in get
    return self._get(request.path, request.method, "")
  File "/home/baongocst/anaconda3/envs/python36/lib/python3.6/site-packages/sanic/router.py", line 469, in _get
    raise NotFound("Requested URL {} not found".format(url))
sanic.exceptions.NotFound: Requested URL /socket.io/ not found
2019-07-17 15:09:37,815 [ERROR]  Exception occurred while handling uri: 'http://localhost:5005/socket.io/?EIO=3&transport=polling&t=Ml--Y8B'
Traceback (most recent call last):
  File "/home/baongocst/anaconda3/envs/python36/lib/python3.6/site-packages/sanic/app.py", line 893, in handle_request
    handler, args, kwargs, uri = self.router.get(request)
  File "/home/baongocst/anaconda3/envs/python36/lib/python3.6/site-packages/sanic/router.py", line 407, in get
    return self._get(request.path, request.method, "")
  File "/home/baongocst/anaconda3/envs/python36/lib/python3.6/site-packages/sanic/router.py", line 469, in _get
    raise NotFound("Requested URL {} not found".format(url))
sanic.exceptions.NotFound: Requested URL /socket.io/ not found
2019-07-17 15:09:37,821 [ERROR]  Exception occurred while handling uri: 'http://localhost:5005/socket.io/?EIO=3&transport=polling&t=Ml--eUR'
Traceback (most recent call last):
  File "/home/baongocst/anaconda3/envs/python36/lib/python3.6/site-packages/sanic/app.py", line 893, in handle_request
    handler, args, kwargs, uri = self.router.get(request)
  File "/home/baongocst/anaconda3/envs/python36/lib/python3.6/site-packages/sanic/router.py", line 407, in get
    return self._get(request.path, request.method, "")
  File "/home/baongocst/anaconda3/envs/python36/lib/python3.6/site-packages/sanic/router.py", line 469, in _get
    raise NotFound("Requested URL {} not found".format(url))
sanic.exceptions.NotFound: Requested URL /socket.io/ not found
2019-07-17 15:09:44,035 [ERROR]  Exception occurred while handling uri: 'http://localhost:5005/socket.io/?EIO=3&transport=polling&t=Ml--kLR'
Traceback (most recent call last):
  File "/home/baongocst/anaconda3/envs/python36/lib/python3.6/site-packages/sanic/app.py", line 893, in handle_request
    handler, args, kwargs, uri = self.router.get(request)
  File "/home/baongocst/anaconda3/envs/python36/lib/python3.6/site-packages/sanic/router.py", line 407, in get
    return self._get(request.path, request.method, "")
  File "/home/baongocst/anaconda3/envs/python36/lib/python3.6/site-packages/sanic/router.py", line 469, in _get
    raise NotFound("Requested URL {} not found".format(url))
sanic.exceptions.NotFound: Requested URL /socket.io/ not found
2019-07-17 15:09:50,037 [ERROR]  Exception occurred while handling uri: 'http://localhost:5005/socket.io/?EIO=3&transport=polling&t=Ml--lpC'
Traceback (most recent call last):
  File "/home/baongocst/anaconda3/envs/python36/lib/python3.6/site-packages/sanic/app.py", line 893, in handle_request
    handler, args, kwargs, uri = self.router.get(request)
  File "/home/baongocst/anaconda3/envs/python36/lib/python3.6/site-packages/sanic/router.py", line 407, in get
    return self._get(request.path, request.method, "")
  File "/home/baongocst/anaconda3/envs/python36/lib/python3.6/site-packages/sanic/router.py", line 469, in _get
    raise NotFound("Requested URL {} not found".format(url))
sanic.exceptions.NotFound: Requested URL /socket.io/ not found
2019-07-17 15:09:56,035 [ERROR]  Exception occurred while handling uri: 'http://localhost:5005/socket.io/?EIO=3&transport=polling&t=Ml--nGx'
Traceback (most recent call last):
  File "/home/baongocst/anaconda3/envs/python36/lib/python3.6/site-packages/sanic/app.py", line 893, in handle_request
    handler, args, kwargs, uri = self.router.get(request)
  File "/home/baongocst/anaconda3/envs/python36/lib/python3.6/site-packages/sanic/router.py", line 407, in get
    return self._get(request.path, request.method, "")
  File "/home/baongocst/anaconda3/envs/python36/lib/python3.6/site-packages/sanic/router.py", line 469, in _get
    raise NotFound("Requested URL {} not found".format(url))
sanic.exceptions.NotFound: Requested URL /socket.io/ not found
2019-07-17 15:10:02,036 [ERROR]  Exception occurred while handling uri: 'http://localhost:5005/socket.io/?EIO=3&transport=polling&t=Ml--oki'
Traceback (most recent call last):
  File "/home/baongocst/anaconda3/envs/python36/lib/python3.6/site-packages/sanic/app.py", line 893, in handle_request
    handler, args, kwargs, uri = self.router.get(request)
  File "/home/baongocst/anaconda3/envs/python36/lib/python3.6/site-packages/sanic/router.py", line 407, in get
    return self._get(request.path, request.method, "")
  File "/home/baongocst/anaconda3/envs/python36/lib/python3.6/site-packages/sanic/router.py", line 469, in _get
    raise NotFound("Requested URL {} not found".format(url))
sanic.exceptions.NotFound: Requested URL /socket.io/ not found
2019-07-17 15:10:08,038 [ERROR]  Exception occurred while handling uri: 'http://localhost:5005/socket.io/?EIO=3&transport=polling&t=Ml--qCS'
Traceback (most recent call last):
  File "/home/baongocst/anaconda3/envs/python36/lib/python3.6/site-packages/sanic/app.py", line 893, in handle_request
    handler, args, kwargs, uri = self.router.get(request)
  File "/home/baongocst/anaconda3/envs/python36/lib/python3.6/site-packages/sanic/router.py", line 407, in get
    return self._get(request.path, request.method, "")
  File "/home/baongocst/anaconda3/envs/python36/lib/python3.6/site-packages/sanic/router.py", line 469, in _get
    raise NotFound("Requested URL {} not found".format(url))
sanic.exceptions.NotFound: Requested URL /socket.io/ not found
2019-07-17 15:10:14,038 [ERROR]  Exception occurred while handling uri: 'http://localhost:5005/socket.io/?EIO=3&transport=polling&t=Ml--rgC'
Traceback (most recent call last):
  File "/home/baongocst/anaconda3/envs/python36/lib/python3.6/site-packages/sanic/app.py", line 893, in handle_request
    handler, args, kwargs, uri = self.router.get(request)
  File "/home/baongocst/anaconda3/envs/python36/lib/python3.6/site-packages/sanic/router.py", line 407, in get
    return self._get(request.path, request.method, "")
  File "/home/baongocst/anaconda3/envs/python36/lib/python3.6/site-packages/sanic/router.py", line 469, in _get
    raise NotFound("Requested URL {} not found".format(url))
sanic.exceptions.NotFound: Requested URL /socket.io/ not found
2019-07-17 15:10:20,035 [ERROR]  Exception occurred while handling uri: 'http://localhost:5005/socket.io/?EIO=3&transport=polling&t=Ml--t7y'
Traceback (most recent call last):
  File "/home/baongocst/anaconda3/envs/python36/lib/python3.6/site-packages/sanic/app.py", line 893, in handle_request
    handler, args, kwargs, uri = self.router.get(request)
  File "/home/baongocst/anaconda3/envs/python36/lib/python3.6/site-packages/sanic/router.py", line 407, in get
    return self._get(request.path, request.method, "")
  File "/home/baongocst/anaconda3/envs/python36/lib/python3.6/site-packages/sanic/router.py", line 469, in _get
    raise NotFound("Requested URL {} not found".format(url))
sanic.exceptions.NotFound: Requested URL /socket.io/ not found
2019-07-17 15:10:26,044 [ERROR]  Exception occurred while handling uri: 'http://localhost:5005/socket.io/?EIO=3&transport=polling&t=Ml--ubi'
Traceback (most recent call last):
  File "/home/baongocst/anaconda3/envs/python36/lib/python3.6/site-packages/sanic/app.py", line 893, in handle_request
    handler, args, kwargs, uri = self.router.get(request)
  File "/home/baongocst/anaconda3/envs/python36/lib/python3.6/site-packages/sanic/router.py", line 407, in get
    return self._get(request.path, request.method, "")
  File "/home/baongocst/anaconda3/envs/python36/lib/python3.6/site-packages/sanic/router.py", line 469, in _get
    raise NotFound("Requested URL {} not found".format(url))
sanic.exceptions.NotFound: Requested URL /socket.io/ not found
2019-07-17 15:17:25,501 [DEBUG]  Available web server routes: 
/webhooks/rest                                     GET                            custom_webhook_CmdlineInput.health
/webhooks/rest/webhook                             POST                           custom_webhook_CmdlineInput.receive
2019-07-17 15:18:51,502 [ERROR]  Exception occurred while handling uri: 'http://localhost:5005/socket.io/?EIO=3&transport=polling&t=Ml_0ePx'
Traceback (most recent call last):
  File "/home/baongocst/anaconda3/envs/python36/lib/python3.6/site-packages/sanic/app.py", line 893, in handle_request
    handler, args, kwargs, uri = self.router.get(request)
  File "/home/baongocst/anaconda3/envs/python36/lib/python3.6/site-packages/sanic/router.py", line 407, in get
    return self._get(request.path, request.method, "")
  File "/home/baongocst/anaconda3/envs/python36/lib/python3.6/site-packages/sanic/router.py", line 469, in _get
    raise NotFound("Requested URL {} not found".format(url))
sanic.exceptions.NotFound: Requested URL /socket.io/ not found
2019-07-17 15:18:51,511 [ERROR]  Exception occurred while handling uri: 'http://localhost:5005/socket.io/?EIO=3&transport=polling&t=Ml_0kmB'
Traceback (most recent call last):
  File "/home/baongocst/anaconda3/envs/python36/lib/python3.6/site-packages/sanic/app.py", line 893, in handle_request
    handler, args, kwargs, uri = self.router.get(request)
  File "/home/baongocst/anaconda3/envs/python36/lib/python3.6/site-packages/sanic/router.py", line 407, in get
    return self._get(request.path, request.method, "")
  File "/home/baongocst/anaconda3/envs/python36/lib/python3.6/site-packages/sanic/router.py", line 469, in _get
    raise NotFound("Requested URL {} not found".format(url))
sanic.exceptions.NotFound: Requested URL /socket.io/ not found
2019-07-17 15:19:05,549 [ERROR]  Exception occurred while handling uri: 'http://localhost:5005/socket.io/?EIO=3&transport=polling&t=Ml_0r6R'
Traceback (most recent call last):
  File "/home/baongocst/anaconda3/envs/python36/lib/python3.6/site-packages/sanic/app.py", line 893, in handle_request
    handler, args, kwargs, uri = self.router.get(request)
  File "/home/baongocst/anaconda3/envs/python36/lib/python3.6/site-packages/sanic/router.py", line 407, in get
    return self._get(request.path, request.method, "")
  File "/home/baongocst/anaconda3/envs/python36/lib/python3.6/site-packages/sanic/router.py", line 469, in _get
    raise NotFound("Requested URL {} not found".format(url))
sanic.exceptions.NotFound: Requested URL /socket.io/ not found
2019-07-17 15:19:15,060 [ERROR]  Exception occurred while handling uri: 'http://localhost:5005/socket.io/?EIO=3&transport=polling&t=Ml_0v0R'
Traceback (most recent call last):
  File "/home/baongocst/anaconda3/envs/python36/lib/python3.6/site-packages/sanic/app.py", line 893, in handle_request
    handler, args, kwargs, uri = self.router.get(request)
  File "/home/baongocst/anaconda3/envs/python36/lib/python3.6/site-packages/sanic/router.py", line 407, in get
    return self._get(request.path, request.method, "")
  File "/home/baongocst/anaconda3/envs/python36/lib/python3.6/site-packages/sanic/router.py", line 469, in _get
    raise NotFound("Requested URL {} not found".format(url))
sanic.exceptions.NotFound: Requested URL /socket.io/ not found
2019-07-17 15:19:25,953 [ERROR]  Exception occurred while handling uri: 'http://localhost:5005/socket.io/?EIO=3&transport=polling&t=Ml_0xSh'
Traceback (most recent call last):
  File "/home/baongocst/anaconda3/envs/python36/lib/python3.6/site-packages/sanic/app.py", line 893, in handle_request
    handler, args, kwargs, uri = self.router.get(request)
  File "/home/baongocst/anaconda3/envs/python36/lib/python3.6/site-packages/sanic/router.py", line 407, in get
    return self._get(request.path, request.method, "")
  File "/home/baongocst/anaconda3/envs/python36/lib/python3.6/site-packages/sanic/router.py", line 469, in _get
    raise NotFound("Requested URL {} not found".format(url))
sanic.exceptions.NotFound: Requested URL /socket.io/ not found
2019-07-17 15:19:57,311 [ERROR]  Exception occurred while handling uri: 'http://localhost:5005/socket.io/?EIO=3&transport=polling&t=Ml_0zux'
Traceback (most recent call last):
  File "/home/baongocst/anaconda3/envs/python36/lib/python3.6/site-packages/sanic/app.py", line 893, in handle_request
    handler, args, kwargs, uri = self.router.get(request)
  File "/home/baongocst/anaconda3/envs/python36/lib/python3.6/site-packages/sanic/router.py", line 407, in get
    return self._get(request.path, request.method, "")
  File "/home/baongocst/anaconda3/envs/python36/lib/python3.6/site-packages/sanic/router.py", line 469, in _get
    raise NotFound("Requested URL {} not found".format(url))
sanic.exceptions.NotFound: Requested URL /socket.io/ not found
2019-07-17 15:19:58,948 [ERROR]  Exception occurred while handling uri: 'http://localhost:5005/socket.io/?EIO=3&transport=polling&t=Ml_14FB'
Traceback (most recent call last):
  File "/home/baongocst/anaconda3/envs/python36/lib/python3.6/site-packages/sanic/app.py", line 893, in handle_request
    handler, args, kwargs, uri = self.router.get(request)
  File "/home/baongocst/anaconda3/envs/python36/lib/python3.6/site-packages/sanic/router.py", line 407, in get
    return self._get(request.path, request.method, "")
  File "/home/baongocst/anaconda3/envs/python36/lib/python3.6/site-packages/sanic/router.py", line 469, in _get
    raise NotFound("Requested URL {} not found".format(url))
sanic.exceptions.NotFound: Requested URL /socket.io/ not found
2019-07-17 15:20:37,115 [ERROR]  Exception occurred while handling uri: 'http://localhost:5005/socket.io/?EIO=3&transport=polling&t=Ml_15iy'
Traceback (most recent call last):
  File "/home/baongocst/anaconda3/envs/python36/lib/python3.6/site-packages/sanic/app.py", line 893, in handle_request
    handler, args, kwargs, uri = self.router.get(request)
  File "/home/baongocst/anaconda3/envs/python36/lib/python3.6/site-packages/sanic/router.py", line 407, in get
    return self._get(request.path, request.method, "")
  File "/home/baongocst/anaconda3/envs/python36/lib/python3.6/site-packages/sanic/router.py", line 469, in _get
    raise NotFound("Requested URL {} not found".format(url))
sanic.exceptions.NotFound: Requested URL /socket.io/ not found
2019-07-17 15:20:37,131 [ERROR]  Exception occurred while handling uri: 'http://localhost:5005/socket.io/?EIO=3&transport=polling&t=Ml_1C3B'
Traceback (most recent call last):
  File "/home/baongocst/anaconda3/envs/python36/lib/python3.6/site-packages/sanic/app.py", line 893, in handle_request
    handler, args, kwargs, uri = self.router.get(request)
  File "/home/baongocst/anaconda3/envs/python36/lib/python3.6/site-packages/sanic/router.py", line 407, in get
    return self._get(request.path, request.method, "")
  File "/home/baongocst/anaconda3/envs/python36/lib/python3.6/site-packages/sanic/router.py", line 469, in _get
    raise NotFound("Requested URL {} not found".format(url))
sanic.exceptions.NotFound: Requested URL /socket.io/ not found
2019-07-17 15:20:46,199 [ERROR]  Exception occurred while handling uri: 'http://localhost:5005/socket.io/?EIO=3&transport=polling&t=Ml_1FTx'
Traceback (most recent call last):
  File "/home/baongocst/anaconda3/envs/python36/lib/python3.6/site-packages/sanic/app.py", line 893, in handle_request
    handler, args, kwargs, uri = self.router.get(request)
  File "/home/baongocst/anaconda3/envs/python36/lib/python3.6/site-packages/sanic/router.py", line 407, in get
    return self._get(request.path, request.method, "")
  File "/home/baongocst/anaconda3/envs/python36/lib/python3.6/site-packages/sanic/router.py", line 469, in _get
    raise NotFound("Requested URL {} not found".format(url))
sanic.exceptions.NotFound: Requested URL /socket.io/ not found
2019-07-17 15:29:09,650 [ERROR]  Exception occurred while handling uri: 'http://localhost:5005/socket.io/?EIO=3&transport=polling&t=Ml_1HQx'
Traceback (most recent call last):
  File "/home/baongocst/anaconda3/envs/python36/lib/python3.6/site-packages/sanic/app.py", line 893, in handle_request
    handler, args, kwargs, uri = self.router.get(request)
  File "/home/baongocst/anaconda3/envs/python36/lib/python3.6/site-packages/sanic/router.py", line 407, in get
    return self._get(request.path, request.method, "")
  File "/home/baongocst/anaconda3/envs/python36/lib/python3.6/site-packages/sanic/router.py", line 469, in _get
    raise NotFound("Requested URL {} not found".format(url))
sanic.exceptions.NotFound: Requested URL /socket.io/ not found
2019-07-17 15:29:09,682 [ERROR]  Exception occurred while handling uri: 'http://localhost:5005/socket.io/?EIO=3&transport=polling&t=Ml_1NnB'
Traceback (most recent call last):
  File "/home/baongocst/anaconda3/envs/python36/lib/python3.6/site-packages/sanic/app.py", line 893, in handle_request
    handler, args, kwargs, uri = self.router.get(request)
  File "/home/baongocst/anaconda3/envs/python36/lib/python3.6/site-packages/sanic/router.py", line 407, in get
    return self._get(request.path, request.method, "")
  File "/home/baongocst/anaconda3/envs/python36/lib/python3.6/site-packages/sanic/router.py", line 469, in _get
    raise NotFound("Requested URL {} not found".format(url))
sanic.exceptions.NotFound: Requested URL /socket.io/ not found
2019-07-17 15:29:09,689 [ERROR]  Exception occurred while handling uri: 'http://localhost:5005/socket.io/?EIO=3&transport=polling&t=Ml_1U7S'
Traceback (most recent call last):
  File "/home/baongocst/anaconda3/envs/python36/lib/python3.6/site-packages/sanic/app.py", line 893, in handle_request
    handler, args, kwargs, uri = self.router.get(request)
  File "/home/baongocst/anaconda3/envs/python36/lib/python3.6/site-packages/sanic/router.py", line 407, in get
    return self._get(request.path, request.method, "")
  File "/home/baongocst/anaconda3/envs/python36/lib/python3.6/site-packages/sanic/router.py", line 469, in _get
    raise NotFound("Requested URL {} not found".format(url))
sanic.exceptions.NotFound: Requested URL /socket.io/ not found
2019-07-17 15:29:09,696 [ERROR]  Exception occurred while handling uri: 'http://localhost:5005/socket.io/?EIO=3&transport=polling&t=Ml_1aTh'
Traceback (most recent call last):
  File "/home/baongocst/anaconda3/envs/python36/lib/python3.6/site-packages/sanic/app.py", line 893, in handle_request
    handler, args, kwargs, uri = self.router.get(request)
  File "/home/baongocst/anaconda3/envs/python36/lib/python3.6/site-packages/sanic/router.py", line 407, in get
    return self._get(request.path, request.method, "")
  File "/home/baongocst/anaconda3/envs/python36/lib/python3.6/site-packages/sanic/router.py", line 469, in _get
    raise NotFound("Requested URL {} not found".format(url))
sanic.exceptions.NotFound: Requested URL /socket.io/ not found
2019-07-17 15:29:09,703 [ERROR]  Exception occurred while handling uri: 'http://localhost:5005/socket.io/?EIO=3&transport=polling&t=Ml_1gpy'
Traceback (most recent call last):
  File "/home/baongocst/anaconda3/envs/python36/lib/python3.6/site-packages/sanic/app.py", line 893, in handle_request
    handler, args, kwargs, uri = self.router.get(request)
  File "/home/baongocst/anaconda3/envs/python36/lib/python3.6/site-packages/sanic/router.py", line 407, in get
    return self._get(request.path, request.method, "")
  File "/home/baongocst/anaconda3/envs/python36/lib/python3.6/site-packages/sanic/router.py", line 469, in _get
    raise NotFound("Requested URL {} not found".format(url))
sanic.exceptions.NotFound: Requested URL /socket.io/ not found
2019-07-17 15:29:09,710 [ERROR]  Exception occurred while handling uri: 'http://localhost:5005/socket.io/?EIO=3&transport=polling&t=Ml_1nAB'
Traceback (most recent call last):
  File "/home/baongocst/anaconda3/envs/python36/lib/python3.6/site-packages/sanic/app.py", line 893, in handle_request
    handler, args, kwargs, uri = self.router.get(request)
  File "/home/baongocst/anaconda3/envs/python36/lib/python3.6/site-packages/sanic/router.py", line 407, in get
    return self._get(request.path, request.method, "")
  File "/home/baongocst/anaconda3/envs/python36/lib/python3.6/site-packages/sanic/router.py", line 469, in _get
    raise NotFound("Requested URL {} not found".format(url))
sanic.exceptions.NotFound: Requested URL /socket.io/ not found
2019-07-17 15:29:09,715 [ERROR]  Exception occurred while handling uri: 'http://localhost:5005/socket.io/?EIO=3&transport=polling&t=Ml_1zsh'
Traceback (most recent call last):
  File "/home/baongocst/anaconda3/envs/python36/lib/python3.6/site-packages/sanic/app.py", line 893, in handle_request
    handler, args, kwargs, uri = self.router.get(request)
  File "/home/baongocst/anaconda3/envs/python36/lib/python3.6/site-packages/sanic/router.py", line 407, in get
    return self._get(request.path, request.method, "")
  File "/home/baongocst/anaconda3/envs/python36/lib/python3.6/site-packages/sanic/router.py", line 469, in _get
    raise NotFound("Requested URL {} not found".format(url))
sanic.exceptions.NotFound: Requested URL /socket.io/ not found
